Workbook

Sheet Hus Alahmed
B1: Payment on Hus Alahmed to HJM
A3: Month | B3: Date | C3: Description | D3: Rental Amounts | E3: General Expenses | F3: Comments
C4: Fixed Amount
A5: OCT | B5: 45943 | C5: أجار الشقة الشهري - 3 أشخاص - 19 يوم | D5: ='Days each month'!$C$24*'Days each month'!C5 -> 626.54018
E6: ='October 2025'!C85 -> 221.90333 | F6: عزبة أكتوبر 2025 المشتركة
E7: ='October 2025'!C15*(-1) -> 0 | F7: المبلغ المسترجع لشهر أكتوبر 2025
B8: 45944 | C8: دفع لأجار الشقة | D8: -6434 | E8: -222.05 | F8: دفع الدفعة الأولى
B9: 45956 | C9: دفع لأجار الشقة | D9: -1469.5
G10: =SUM(E6:E9) -> -0.14666667
A13: NOV | B13: 45962 | C13: أجار الشقة الشهري - 3 أشخاص - 30 يوم | D13: ='Days each month'!$C$24*'Days each month'!C6 -> 989.27397
C14: دفع لأجار الشقة | D14: -1200
E15: ='November 2025'!C78 -> 74.113333 | F15: عزبة نوفمبر 2025 المشتركة
E16: ='November 2025'!C13*(-1) -> -54 | F16: المبلغ المسترجع لشهر نوفمبر 2025
B17: 45988 | E17: -19.97 | F17: دفع من أبو علي
G18: =SUM(E15:E17) -> 0.14333333
A21: DEC | B21: 45992 | C21: أجار الشقة الشهري - 3 أشخاص - 31 يوم | D21: ='Days each month'!$C$24*'Days each month'!C7 -> 1022.2498
B22: 46016 | C22: دفع لأجار الشقة | D22: -1200
E23: ='December 2025'!C79 -> 38.603333 | F23: عزبة ديسمبر 2025 المشتركة
E24: ='December 2025'!C13*(-1) -> 0 | F24: المبلغ المسترجع لشهر ديسمبر 2025
B25: 46016 | E25: -38.6 | F25: دفع من أبو علي
G26: =SUM(E23:E25) -> 0.0033333333
A29: JAN | B29: 46023 | C29: أجار الشقة الشهري - 3 أشخاص - 31 يوم | D29: ='Days each month'!$C$24*'Days each month'!C8 -> 1022.2498
B30: 46048 | C30: دفع لأجار الشقة | D30: -1000
E31: ='January 2026'!C79 -> 65.983333 | F31: عزبة يناير 2026 المشتركة
E32: ='January 2026'!C13*(-1) -> -48.98 | F32: المبلغ المسترجع لشهر يناير 2026
B33: 46048 | E33: -7 | F33: دفع من أبو علي
G34: =SUM(E31:E33) -> 10.003333
A37: FEB | B37: 46054 | C37: أجار الشقة الشهري - 3 أشخاص - 28 يوم | D37: ='Days each month'!$C$24*'Days each month'!C9 -> 923.32237
C38: دفع لأجار الشقة | D38: -732.67
E39: ='February 2026'!C79 -> 139.73333 | F39: عزبة فبراير 2026 المشتركة
E40: ='February 2026'!C13*(-1) -> -87.5 | F40: المبلغ المسترجع لشهر فبراير 2026
B41: 46078 | E41: -69.45 | F41: دفع من أبو علي
E42: 20 | F42: فطور رمضان بين أبو هادي وأبو علي - الأربعاء
G43: =SUM(E39:E42) -> 2.7833333
A46: MAR | B46: 46082 | C46: أجار الشقة الشهري - 3 أشخاص - 31 يوم | D46: ='Days each month'!$C$24*'Days each month'!C10 -> 1022.2498
E47: ='March 2026'!C83 -> 205.29667 | F47: عزبة مارس 2026 المشتركة
E48: ='March 2026'!C17*(-1) -> -220.15 | F48: المبلغ المسترجع لشهر مارس 2026
E49: -14 | F49: للمعسل بين أبو هادي أبو علي
G51: =SUM(E47:E50) -> -28.853333
A54: APR | B54: 46113 | C54: أجار الشقة الشهري - 3 أشخاص - 30 يوم | D54: ='Days each month'!$C$24*'Days each month'!C11 -> 989.27397
...

Sheet Siraj
B1: Payment on Siraj to Hussain
A3: Month | B3: Date | C3: Description | D3: Rental Amounts | E3: General Expenses | F3: Comments
C4: Fixed Amount
A5: OCT | B5: 45931 | C5: أجار الشقة الشهري - 3 أشخاص - 19 يوم | D5: ='Days each month'!$C$24*'Days each month'!C5 -> 626.54018
C6: مسترجع من شقة حي النفل | D6: -3611.74
E7: =(850/2)+(50/2)+(23/2) -> 461.5 | F7: النقل مرتين + التجليد
E8: ='October 2025'!C85 -> 221.90333 | F8: عزبة أكتوبر 2025 المشتركة
E9: ='October 2025'!C68*(-1) -> 0 | F9: المبلغ المسترجع لشهر أكتوبر 2025
G10: =SUM(E6:E9) -> 683.40333
F11: Siraj Quraish
A12: NOV | B12: 45962 | C12: أجار الشقة الشهري - 3 أشخاص - 30 يوم | D12: ='Days each month'!$C$24*'Days each month'!C6 -> 989.27397
B13: 45981 | C13: دفع لأجار الشقة | D13: -500
B14: 45987 | C14: دفع لأجار الشقة | D14: -1000
E15: ='November 2025'!C78 -> 74.113333 | F15: عزبة نوفمبر 2025 المشتركة
E16: ='November 2025'!C61*(-1) -> -33.5 | F16: المبلغ المسترجع لشهر نوفمبر 2025
E17: -52 | F17: عشاء ربيان مقلى - ١٨ نوفمبر
G18: =SUM(E15:E17) -> -11.386667
F19: Siraj Quraish
A20: DEC | B20: 45992 | C20: أجار الشقة الشهري - 3 أشخاص - 31 يوم | D20: ='Days each month'!$C$24*'Days each month'!C7 -> 1022.2498
E21: ='December 2025'!C79 -> 38.603333 | F21: عزبة ديسمبر 2025 المشتركة
E22: ='December 2025'!C62*(-1) -> 0 | F22: المبلغ المسترجع لشهر ديسمبر 2025
G23: =SUM(E21:E22) -> 38.603333
F24: Siraj Quraish
A25: JAN | B25: 46023 | C25: أجار الشقة الشهري - 3 أشخاص - 31 يوم | D25: ='Days each month'!$C$24*'Days each month'!C8 -> 1022.2498
B26: 46047 | C26: دفع لأجار الشقة | D26: -1000.5
E27: ='January 2026'!C79 -> 65.983333 | F27: عزبة يناير 2026 المشتركة
E28: ='January 2026'!C62*(-1) -> -50 | F28: المبلغ المسترجع لشهر يناير 2026
G29: =SUM(E27:E28) -> 15.983333
F30: Siraj Quraish
A31: FEB | B31: 46054 | C31: أجار الشقة الشهري - 3 أشخاص - 28 يوم | D31: ='Days each month'!$C$24*'Days each month'!C9 -> 923.32237
B32: 46054 | E32: ='February 2026'!C79 -> 139.73333 | F32: عزبة فبراير 2026 المشتركة
E33: ='February 2026'!C62*(-1) -> -90 | F33: المبلغ المسترجع لشهر فبراير 2026
E34: -615 | F34: دفع من أبو فدوى للعزبة
G35: =SUM(E32:E34) -> -565.26667
F36: Siraj Quraish
A37: MAR | B37: 46082 | C37: أجار الشقة الشهري - 3 أشخاص - 31 يوم | D37: ='Days each month'!$C$24*'Days each month'!C10 -> 1022.2498 | E37: ='March 2026'!C83 -> 205.29667 | F37: عزبة مارس 2026 المشتركة
E38: ='March 2026'!C66*(-1) -> -26 | F38: المبلغ المسترجع لشهر مارس 2026
B39: 46084 | E39: -20 | F39: تعبئة بنزين
B40: 46090 | E40: =225/2 -> 112.5 | F40: مخالفة السرعة - نص نص
B41: 46111 | E41: =22.94/2 -> 11.47 | F41: روب يوناني وشوفان
...

Sheet Mahdi BuAli
B1: Payment on Mahdi BuAli to HJM
A3: Month | B3: Date | C3: Description | D3: Rental Amounts | E3: General Expenses | F3: Comments | G3: Column1
A5: MAY | B5: 46144 | C5: أجار الشقة الشهري - 4 أشخاص - 30 يوم | D5: ='Days each month'!$C$25*30 -> 741.95548
B6: 46172 | C6: دفع لأجار الشقة | D6: -741.96
E7: ='May 2026'!C99 -> 96.915 | F7: عزبة مايو 2026 المشتركة
E8: ='May 2026'!C92*(-1) -> -15 | F8: المبلغ المسترجع لشهر مايو 2026
E9: -81.92 | F9: دفع من مهدي
G10: =SUM(E7:E9) -> -0.005
F11: Mahdi
A12: JUN | B12: 46174 | C12: أجار الشقة الشهري - 4 أشخاص - 30 يوم | D12: ='Days each month'!$C$25*'Days each month'!C13 -> 741.95548
C13: دفع لأجار الشقة | D13: -741.96
E14: ='June 2026'!C98 -> 123.415 | F14: عزبة جون 2026 المشتركة
E15: ='June 2026'!C92*(-1) -> -68 | F15: المبلغ المسترجع لشهر جون 2026
E16: -55.42 | F16: دفع من مهدي
G17: =SUM(E14:E16) -> -0.005
F19: Mahdi
A20: JUL | B20: 46204 | C20: أجار الشقة الشهري - 4 أشخاص - 19 يوم | D20: ='Days each month'!$C$25*19 -> 469.90514
C21: دفع لأجار الشقة | D21: -469.9 | E21: ='July 2026'!C99 -> 114.015 | F21: عزبة جولاي 2026 المشتركة
E22: ='July 2026'!C93*(-1) -> 0 | F22: المبلغ المسترجع لشهر جولاي 2026
E23: -114.01
G25: =SUM(E21:E24) -> 0.005
F26: Mahdi
B34: Rental Expiry
B35: 46308
D36: Remaining for Rental | E36: Remaining for General Expenses
D37: =SUM(D5:D28) -> -0.0039041096 | E37: =SUM(E5:E29) -> -0.005

Sheet Main Expenses (Fixed)
A1: CAPEX Paid by Hussain
A3: Payments by Hussain
A4: Date | B4: Description | C4: Amount | D4: Paid By
A6: 45943 | B6: أجار سنة كاملة October 14 2025 to October 13 2026 | C6: 30700 | D6: Hussain Almoghalliq
A7: 45943 | B7: مدفوعات المكتب العقاري للإيجار - مرة واحدة فقط | C7: 2500 | D7: Hussain Almoghalliq
A8: 45950 | B8: مكيف الصالة المشترك | C8: 1408.5 | D8: Hussain Almoghalliq
A9: 45951 | B9: شغل الباب والجبس المشترك | C9: 1500 | D9: Hussain Almoghalliq
B13: المجموع | C13: =SUM(C5:C12) -> 36108.5
B15: الأجار الشهري على المجموعة | C15: =C13/12 -> 3009.0417
B16: الأجار اليومي الكامل للشقة | C16: =C13/365 -> 98.927397
B17: الأجار اليومي على الشخص - ٣ أشخاص | C17: =C16/3 -> 32.975799
B18: الأجار اليومي على الشخص - 4 أشخاص | C18: =C16/4 -> 24.731849
B19: الأجار الفردي على الشخص (ابو هادي + سراج + أبو علي) | C19: =C15/3 -> 1003.0139
B27: Final Share on Each Member (fixed) | C27: =C13/3 -> 12036.167

Sheet Days each month
B4: الشهر | C4: عدد الأيام | D4: المبلغ الشهري المتوقع على كل شخص
B5: 45931 | C5: 19 | D5: =$C$24*C5 -> 626.54018
B6: 45962 | C6: 30 | D6: =$C$24*C6 -> 989.27397
B7: 45992 | C7: 31 | D7: =$C$24*C7 -> 1022.2498
B8: 46023 | C8: 31 | D8: =$C$24*C8 -> 1022.2498
B9: 46054 | C9: 28 | D9: =$C$24*C9 -> 923.32237
B10: 46082 | C10: 31 | D10: =$C$24*C10 -> 1022.2498 | H10: Special Case for April
B11: 46113 | C11: 30 | D11: =$C$24*C11 -> 989.27397 | H11: 24 days by 3 members | I11: 24 | J11: =I11*C24 -> 791.41918
B12: 46143 | C12: 31 | D12: =$C$24*C12 -> 1022.2498 | H12: 6 days by 4 members | I12: 6 | J12: =I12*C25 -> 148.3911
B13: 46174 | C13: 30 | D13: =$C$24*C13 -> 989.27397
B14: 46204 | C14: 31 | D14: =$C$24*C14 -> 1022.2498
B15: 46235 | C15: 31 | D15: =$C$24*C15 -> 1022.2498
B16: 46266 | C16: 30 | D16: =$C$24*C16 -> 989.27397 | H16: Special Case for July
B17: 46296 | C17: 12 | D17: =$C$24*C17 -> 395.70959 | H17: 12 days by 3 members | I17: 12 | J17: =I17*C30 -> 0
D18: =$C$24*C18 -> 0 | H18: 19 days by 4 members | I18: 19 | J18: =I18*C31 -> 0
D19: =$C$24*C19 -> 0
D20: =$C$24*C20 -> 0
B21: Total | C21: =SUM(C5:C18) -> 365 | D21: =$C$24*C21 -> 12036.167
E23: =D21*3 -> 36108.5
B24: الأجار اليومي على الشخص - ٣ أشخاص | C24: ='Main Expenses (Fixed)'!C17 -> 32.975799
B25: الأجار اليومي على الشخص - 4 أشخاص | C25: ='Main Expenses (Fixed)'!C18 -> 24.731849
B26: الأجار اليومي الكامل للشقة - بغض النظر عن العدد | C26: ='Main Expenses (Fixed)'!C16 -> 98.927397
D30: Month/Name | E30: Hussain Alahmed | F30: Siraj | G30: Abu Hadi | H30: Mahdi
D31: October | E31: 626.54018 | F31: 626.54018 | G31: 626.54018 | H31: 0
D32: November | E32: 989.27397 | F32: 989.27397 | G32: 989.27397 | H32: 0
D33: December | E33: 1022.2498 | F33: 1022.2498 | G33: 1022.2498 | H33: 0
D34: January | E34: 1022.2498 | F34: 1022.2498 | G34: 1022.2498 | H34: 0
D35: February | E35: 923.32237 | F35: 923.32237 | G35: 923.32237 | H35: 0
D36: March | E36: 1022.2498 | F36: 1022.2498 | G36: 1022.2498 | H36: 0
D37: April | E37: 989.27397 | F37: 989.27397 | G37: 989.27397 | H37: 0
D38: May | E38: 32.975799 | F38: 32.975799 | G38: 32.975799 | H38: 0
D39: May | E39: 741.95548 | F39: 741.95548 | G39: 741.95548 | H39: 741.95548
D40: June | E40: 741.95548 | F40: 741.95548 | G40: 741.95548 | H40: 741.95548
D41: July | E41: 469.90514 | F41: 469.90514 | G41: 469.90514 | H41: 469.90514
D42: July | E42: 395.70959 | F42: 395.70959 | G42: 395.70959 | H42: 0
... D45: October | E45: 395.70959 | F45: 395.70959 | G45: 395.70959 | H45: 0
D47: Total | E47: =SUM(E31:E46) -> 11384.895 | F47: =E47 -> 11384.895 | G47: =E47 -> 11384.895 | H47: =SUM(H39:H46) -> 1953.8161
G50: Grand Total | H50: =SUM(E47:H47) -> 36108.5

Sheet October 2025
A1: Month: October 2025
A5: Payments by Hus Alahmed
A7: Date | B7: Description | C7: Amount | D7: Paid By
D8: Hussain Alahmed
B15: Total | C15: =SUM(C8:C14) -> 0
A20: Payments by Hussain
A22: Date | B22: Description | C22: Amount | D22: Paid By
A23: 45951 | B23: تنظيف الشقة - غسيل | C23: 150 | D23: Hussain Almoghalliq
B24: كيلون الباب | C24: 30 | D24: Hussain Almoghalliq
A25: 45958 | B25: غسيل السجادة | C25: 120 | D25: Hussain Almoghalliq
B26: أغراض من تيمو | C26: =457.06-25.38-13.41-72.2 -> 346.07 | D26: Hussain Almoghalliq
B27: تيمو - مثبت الأبواب | C27: 19.64 | D27: Hussain Almoghalliq
B40: Total | C40: =SUBTOTAL(109,C23:C39) -> 665.71
A47: Payments by Seraj
A49: Date | B49: Description | C49: Amount | D49: Paid By
D50: Siraj Quraish
C68: =SUM(C50:C67) -> 0
B84: Total | C84: =C15+C40+C68 -> 665.71
B85: Share on Each Member (3 members) | C85: =C84/3 -> 221.90333

Sheet November 2025
A1: Month: November 2025
A5: Payments by Hus Alahmed
A7: Date | B7: Description | C7: Amount | D7: Paid By
B8: كلينكس | C8: 30 | D8: Hussain Alahmed
B9: كرتونين ماي | C9: 24 | D9: Hussain Alahmed
B13: Total | C13: =SUM(C8:C12) -> 54
A18: Payments by Hussain
A20: Date | B20: Description | C20: Amount | D20: Paid By
B21: Tape | C21: 5.49 | D21: Hussain Almoghalliq
B22: فاتورة الكهرباء | C22: 63.65 | D22: Hussain Almoghalliq
B23: كرتونين ماي we | C23: 20 | D23: Hussain Almoghalliq
B24: أكياس زبالة + سفر من على كيفك | C24: 45.7 | D24: Hussain Almoghalliq
B34: Total | C34: =SUM(C21:C33) -> 134.84
A41: Payments by Seraj
A43: Date | B43: Description | C43: Amount | D43: Paid By
B44: كيبل AUX | C44: 10 | D44: Siraj Quraish
B45: كرتون ماي | C45: 11 | D45: Siraj Quraish
B46: مشروبات غازية | C46: 12.5 | D46: Siraj Quraish
B61: Total | C61: =SUM(C44:C60) -> 33.5
B77: Total | C77: =C13+C34+C61 -> 222.34
B78: Share on Each Member (3 members) | C78: =C77/3 -> 74.113333

Sheet December 2025
A1: Month: December 2025
A5: Payments by Hus Alahmed
A7: Date | B7: Description | C7: Amount | D7: Paid By
D8: Hussain Alahmed
B13: Total | C13: =SUM(C8:C12) -> 0
A18: Payments by Hussain
A20: Date | B20: Description | C20: Amount | D20: Paid By
B21: فاتورة الكهرباء | C21: 115.81 | D21: Hussain Almoghalliq
B34: Total | C34: =SUM(C21:C33) -> 115.81
A41: Payments by Seraj
A43: Date | B43: Description | C43: Amount | D43: Paid By
D44: Siraj Quraish
B62: Total | C62: =SUM(C44:C61) -> 0
B78: Total | C78: =C13+C34+C62 -> 115.81
B79: Share on Each Member (3 members) | C79: =C78/3 -> 38.603333

Sheet January 2026
A1: Month: January 2026
A5: Payments by Hus Alahmed
A7: Date | B7: Description | C7: Amount | D7: Paid By
B8: كرتونين ماي | C8: 23.98 | D8: Hussain Alahmed
B9: سفر + شوك + ملاعق | C9: 25 | D9: Hussain Alahmed
B13: Total | C13: =SUM(C8:C12) -> 48.98
A18: Payments by Hussain
A20: Date | B20: Description | C20: Amount | D20: Paid By
B21: فاتورة الكهرباء | C21: 86.97 | D21: Hussain Almoghalliq
B22: قربة ماي للشاي والقهوة | C22: 12 | D22: Hussain Almoghalliq
B34: Total | C34: =SUM(C21:C33) -> 98.97
A41: Payments by Seraj
A43: Date | B43: Description | C43: Amount | D43: Paid By
B44: كرتون ماي | C44: 10 | D44: Siraj Quraish
A45: 46046 | B45: كرتون ماي | C45: 10 | D45: Siraj Quraish
B46: إشتراك IPTV | C46: 30 | D46: Siraj Quraish
B62: Total | C62: =SUM(C44:C61) -> 50
B78: Total | C78: =C13+C34+C62 -> 197.95
B79: Share on Each Member (3 members) | C79: =C78/3 -> 65.983333

Sheet February 2026
A1: Month: February 2026
A5: Payments by Hus Alahmed
A7: Date | B7: Description | C7: Amount | D7: Paid By
B8: اغراش ماي | C8: 4 | D8: Hussain Alahmed
B9: كلينكس + مغرفة + طرمبة ماي | C9: 29.5 | D9: Hussain Alahmed
B10: قربة ماي | C10: 8 | D10: Hussain Alahmed
B11: مندي مع رز ابيض - الثلاثاء 25 فبراير | C11: 46 | D11: Hussain Alahmed
B13: Total | C13: =SUM(C8:C12) -> 87.5
A18: Payments by Hussain
A20: Date | B20: Description | C20: Amount | D20: Paid By
B21: فاتورة الكهرباء | C21: 84.36 | D21: Hussain Almoghalliq
B22: فشار | C22: 42 | D22: Hussain Almoghalliq
B23: كرتون ماي - رمضان | C23: 10 | D23: Hussain Almoghalliq
B24: فلينة لرمضان | C24: 20 | D24: Hussain Almoghalliq
B25: فطور الأثنين ٢٣ فبراير - حبة مندي دجاج | C25: 48 | D25: Hussain Almoghalliq
B26: دبس صغير من الرياض | C26: 11.5 | D26: Hussain Almoghalliq
B27: موز + حليب | C27: 25.84 | D27: Hussain Almoghalliq
B34: Total | C34: =SUM(C21:C33) -> 241.7
A41: Payments by Seraj
A43: Date | B43: Description | C43: Amount | D43: Paid By
B44: توصيلة كهرباء قوية | C44: 80 | D44: Siraj Quraish
B45: كرتون ماي | C45: 10 | D45: Siraj Quraish
B62: Total | C62: =SUM(C44:C61) -> 90
B78: Total | C78: =C13+C34+C62 -> 419.2
B79: Share on Each Member (3 members) | C79: =C78/3 -> 139.73333

Sheet March 2026
A1: Month: March 2026
A5: Payments by Hus Alahmed
A7: Date | B7: Description | C7: Amount | D7: Paid By
B8: فشار | C8: 42 | D8: Hussain Alahmed
B9: الثلاثاء - حبة الا ربع مندي | C9: 38 | D9: Hussain Alahmed
B10: صحن كبير للأكل | C10: 35.95 | D10: Hussain Alahmed
B11: بيتزا | C11: 22 | D11: Hussain Alahmed
B12: سكر مع شاي | C12: 62.2 | D12: Hussain Alahmed
A13: 46112 | B13: تبديل غرشة الماي + ملاعق بلاستيك | C13: 20 | D13: Hussain Alahmed
B17: Total | C17: =SUM(C8:C16) -> 220.15
A22: Payments by Hussain
A24: Date | B24: Description | C24: Amount | D24: Paid By
A25: 46082 | B25: الأحد - نص مندي نص مقلوبة | C25: 48 | D25: Hussain Almoghalliq
A26: 46083 | B26: الأثنين - نص مندي فقط ٢ مارس | C26: 23 | D26: Hussain Almoghalliq
B27: تمر | C27: 28 | D27: Hussain Almoghalliq
B28: كرتونين ماي + فيمتو | C28: 34.95 | D28: Hussain Almoghalliq
B29: موز | C29: 8.16 | D29: Hussain Almoghalliq
A30: 46089 | B30: نص مندي + ربع مندي ٨ مارس | C30: 38 | D30: Hussain Almoghalliq
A31: 46091 | B31: نص مندي + ربع مندي ١٠ مارس | C31: 39 | D31: Hussain Almoghalliq
B32: قشطة | C32: 4 | D32: Hussain Almoghalliq
A33: 46093 | B33: فاتورة الكهرباء | C33: 124.63 | D33: Hussain Almoghalliq
B34: كرتونين ماي ماركة وي | C34: 22 | D34: Hussain Almoghalliq
B38: Total | C38: =SUM(C25:C37) -> 369.74
A45: Payments by Seraj
A47: Date | B47: Description | C47: Amount | D47: Paid By
B48: نعناع | C48: 1 | D48: Siraj Quraish
B49: عصير رمان | C49: 25 | D49: Siraj Quraish
B66: Total | C66: =SUM(C48:C65) -> 26
B82: Total | C82: =C17+C38+C66 -> 615.89
B83: Share on Each Member (3 members) | C83: =C82/3 -> 205.29667

Sheet April 2026
A1: Month: April 2026
A5: Payments by Hus Alahmed
A7: Date | B7: Description | C7: Amount | D7: Paid By
A8: 46130 | B8: كرتونين ماي وي | C8: 22 | D8: Hussain Alahmed
B9: تبديل غرشة الماء الكبيرة | C9: 8 | D9: Hussain Alahmed
B17: Total | C17: =SUM(C8:C16) -> 30
A22: Payments by Hussain
A24: Date | B24: Description | C24: Amount | D24: Paid By
B25: ريحة للحمامات | C25: 17.4 | D25: Hussain Almoghalliq
B26: ملاعق بلاستيك مع مناقيش | C26: 11.5 | D26: Hussain Almoghalliq
A27: 46124 | B27: فاتورة الكهرباء | C27: 110.31 | D27: Hussain Almoghalliq
B28: تيب كهرباء أسود | C28: 2 | D28: Hussain Almoghalliq
B29: سويتشات كهرباء | C29: 30 | D29: Hussain Almoghalliq
B38: Total | C38: =SUM(C25:C37) -> 171.21
A45: Payments by Seraj
A47: Date | B47: Description | C47: Amount | D47: Paid By
D48: Siraj Quraish
B66: Total | C66: =SUM(C48:C65) -> 0
B82: Total | C82: =C17+C38+C66 -> 201.21
B83: Share on Each Member (3 members) | C83: =C82/3 -> 67.07

Sheet May 2026
A1: Month: May 2026
A5: Payments by Hus Alahmed
A7: Date | B7: Description | C7: Amount | D7: Paid By
B8: غرشة ماي | C8: 8 | D8: Hussain Alahmed
B9: ملطف جو | C9: 35.9 | D9: Hussain Alahmed
B10: تبديل ماي + شراء وحدة جديدة | C10: 24 | D10: Hussain Alahmed
B17: Total | C17: =SUM(C8:C16) -> 67.9
A22: Payments by Hussain
A24: Date | B24: Description | C24: Amount | D24: Paid By
B25: ملاعق وشوك | C25: 11.5 | D25: Hussain Almoghalliq
B26: كرتونين ماي | C26: 22 | D26: Hussain Almoghalliq
B27: كلينكس | C27: 24 | D27: Hussain Almoghalliq
A28: 46155 | B28: فاتورة الكهرباء | C28: 247.26 | D28: Hussain Almoghalliq
B38: Total | C38: =SUM(C25:C37) -> 304.76
A45: Payments by Seraj
A47: Date | B47: Description | C47: Amount | D47: Paid By
D48: Siraj Quraish
B66: Total | C66: =SUM(C48:C65) -> 0
A71: Payments by Mahdi
A73: Date | B73: Description | C73: Amount | D73: Paid By
B74: كرتون ماي | C74: 15 | D74: Mahdi
B92: Total | C92: =SUM(C74:C91) -> 15
B98: Total | C98: =C17+C38+C66+C92 -> 387.66
B99: Share on Each Member (4 members) | C99: =C98/4 -> 96.915

Sheet June 2026
A1: Month: June 2026
A5: Payments by Hus Alahmed
A7: Date | B7: Description | C7: Amount | D7: Paid By
B8: كرتونين ماي إيفال | C8: 23.98 | D8: Hussain Alahmed
B17: Total | C17: =SUM(C8:C16) -> 23.98
A22: Payments by Hussain
A24: Date | B24: Description | C24: Amount | D24: Paid By
B25: ملطف جو مع رائحة للحمام | C25: 35.95 | D25: Hussain Almoghalliq
B26: فاتورة الكهرباء | C26: 355.73 | D26: Hussain Almoghalliq
B38: Total | C38: =SUM(C25:C37) -> 391.68
A45: Payments by Seraj
A47: Date | B47: Description | C47: Amount | D47: Paid By
B48: صابون يد للحمام | C48: 10 | D48: Siraj Quraish
B66: Total | C66: =SUM(C48:C65) -> 10
A71: Payments by Mahdi
A73: Date | B73: Description | C73: Amount | D73: Paid By
B74: كرتون ماي | C74: 18 | D74: Mahdi
B75: صابون يد | C75: 20 | D75: Mahdi
B76: 3 كراتين ماء | C76: 30 | D76: Mahdi
B92: Total | C92: =SUM(C74:C91) -> 68
B97: Total | C97: =C17+C38+C66+C92 -> 493.66
B98: Share on Each Member (4 members) | C98: =C97/4 -> 123.415

Sheet July 2026
A1: Month: July 2026
A5: Payments by Hus Alahmed
A7: Date | B7: Description | C7: Amount | D7: Paid By
D8: Hussain Alahmed
B17: Total | C17: =SUM(C8:C16) -> 0
A22: Payments by Hussain
A24: Date | B24: Description | C24: Amount | D24: Paid By
B25: تبديل قربتين ماي | C25: 16 | D25: Hussain Almoghalliq
B26: كلينكس | C26: 10 | D26: Hussain Almoghalliq
B27: كرتونين ماي وي 330 مل | C27: 22 | D27: Hussain Almoghalliq
A28: 46216 | B28: فاتورة الكهرباء | C28: 391.95 | D28: Hussain Almoghalliq
A29: 46210 | B29: هاندل لشامبو | C29: 16.11 | D29: Hussain Almoghalliq
B39: Total | C39: =SUM(C25:C38) -> 456.06
A46: Payments by Seraj
A48: Date | B48: Description | C48: Amount | D48: Paid By
D49: Siraj Quraish
B67: Total | C67: =SUM(C49:C66) -> 0
A72: Payments by Mahdi
A74: Date | B74: Description | C74: Amount | D74: Paid By
D75: Mahdi
B93: Total | C93: =SUM(C75:C92) -> 0
B98: Total | C98: =C17+C39+C67+C93 -> 456.06
B99: Share on Each Member (4 members) | C99: =C98/4 -> 114.015

Sheet August 2026
A1: Month: August 2026
A5: Payments by Ahmed
A7: Date | B7: Description | C7: Amount | D7: Paid By
B8: فيري + فرشاة تنظيف | C8: 14.7 | D8: Hussain Alahmed
B9: تعبئة قربة ماء | C9: 8 | D9: Hussain Alahmed
A10: 46256 | B10: كرتونين ماي | C10: 22 | D10: Hussain Alahmed
B13: Total | C13: =SUM(C8:C12) -> 44.7
A18: Payments by Hussain
A20: Date | B20: Description | C20: Amount | D20: Paid By
A21: 46221 | B21: 3 كراتين ماي وي 330 مل | C21: 33 | D21: Hussain Almoghalliq
A22: 46239 | B22: صابون | C22: 15 | D22: Hussain Almoghalliq
A23: 46239 | B23: كرتونين ماي | C23: 22 | D23: Hussain Almoghalliq
A24: 46247 | B24: فاتورة الكهرباء | C24: 376.8 | D24: Hussain Almoghalliq
A25: 46256 | B25: كرتونين ماي | C25: 22 | D25: Hussain Almoghalliq
B34: Total | C34: =SUM(C21:C33) -> 468.8
A41: Payments by Seraj
A43: Date | B43: Description | C43: Amount | D43: Paid By
D44: Siraj Quraish
B62: Total | C62: =SUM(C44:C61) -> 0
B71: Total | C71: =C13+C34+C62 -> 513.5
B72: Share on Each Member (4 members) | C72: =C71/3 -> 171.16667

Sheet September 2026
A1: Month: September 2026
A5: Payments by Hus Alahmed
A7: Date | B7: Description | C7: Amount | D7: Paid By
D8: Hussain Alahmed
B13: Total | C13: =SUM(C8:C12) -> 0
A18: Payments by Hussain
A20: Date | B20: Description | C20: Amount | D20: Paid By
D21: Hussain Almoghalliq
B34: Total | C34: =SUM(C21:C33) -> 0
A41: Payments by Seraj
A43: Date | B43: Description | C43: Amount | D43: Paid By
D44: Siraj Quraish
B62: Total | C62: =SUM(C44:C61) -> 0
B74: Total | C74: =C13+C34+C62 -> 0
B75: Share on Each Member (4 members) | C75: =C74/3 -> 0

Sheet October 2026
A1: Month: October 2026
A5: Payments by Hus Alahmed
A7: Date | B7: Description | C7: Amount | D7: Paid By
B8: test | D8: Hussain Alahmed
B13: Total | C13: =SUM(C8:C12) -> 0
A18: Payments by Hussain
A20: Date | B20: Description | C20: Amount | D20: Paid By
D21: Hussain Almoghalliq
B34: Total | C34: =SUM(C21:C33) -> 0
A41: Payments by Seraj
A43: Date | B43: Description | C43: Amount | D43: Paid By
D44: Siraj Quraish
B62: Total | C62: =SUM(C44:C61) -> 0
B72: Total | C72: =C13+C34+C62 -> 0
B73: Share on Each Member (4 members) | C73: =C72/3 -> 0
